<?xml version="1.0" encoding="utf-8"?>
<mujoco>
	<compiler angle="radian" coordinate="local" meshdir="../stls/fetch" texturedir="../textures"></compiler>
	<option timestep="0.002">
		<flag warmstart="enable"></flag>
	</option>

	<include file="shared.xml"></include>

	<worldbody>
		<geom name="floor0" pos="0.8 0.75 0" size="0.85 0.7 1" type="plane" condim="3" material="floor_mat"></geom>
		<body name="floor0" pos="0.8 0.75 0">
			<site name="target0" pos="0 0 0.5" size="0.02 0.02 0.02" rgba="1 0 0 1" type="sphere"></site>
		</body>

		<include file="robot.xml"></include>


       <body pos="1.40 0.75 0.2" name="table0">
			<geom size="0.25 0.55 0.2" type="box" mass="2000" material="table_mat"></geom>
		</body>

        <body name="door_0" pos="1.5 0.65 0.6" axisangle="0 0 1 149.25">
            <joint name="door_0_joint" pos="-0.1 0 0" axis="0 0 1" type="hinge" limited="true" range="-1.507 0"
                   damping="10" armature="0"/>
            <geom type="box" pos="0 0 0" size="0.1 0.005 0.2" rgba="0 0.5 1 1" contype="1" conaffinity="1"/>
            <geom type="box" pos="0.05 -0.04 0" size="0.05 0.005 0.005" rgba=".75 .75 .75 1" contype="1"
                  conaffinity="1"/>
            <geom type="box" pos="0.095 -0.025 0" size="0.005 0.01975 0.005" rgba=".75 .75 .75 1" contype="1"
                  conaffinity="1"/>
            <site name="door_0_handle" pos="0.05 -0.04 0" size="0.01" rgba="1 0 0 1"/>
        </body>
        <body name="door_1" pos="1.5 0.3 0.6" axisangle="0 0 1 149.25" >
            <joint name="door_1_joint" pos="-0.1 0 0" axis="0 0 1" type="hinge" limited="true" range="-1.507 0"
                   damping="10" armature="0"/>
            <geom type="box" pos="0 0 0" size="0.1 0.005 0.2" rgba="1 0.5 0.5 1" contype="1" conaffinity="1"/>
            <geom type="box" pos="0.05 -0.04 0" size="0.05 0.005 0.005" rgba=".75 .75 .75 1" contype="1"
                  conaffinity="1"/>
            <geom type="box" pos="0.095 -0.025 0" size="0.005 0.01975 0.005" rgba=".75 .75 .75 1" contype="1"
                  conaffinity="1"/>
            <site name="door_1_handle" pos="0.05 -0.04 0" size="0.01" rgba="1 0 0 1"/>
        </body>
        <body name="door_2" pos="1.5 1.05 0.6" axisangle="0 0 1 149.25">
            <joint name="door_2_joint" pos="-0.1 0 0" axis="0 0 1" type="hinge" limited="true" range="-1.507 0"
                   damping="10" armature="0"/>
            <geom type="box" pos="0 0 0" size="0.1 0.005 0.2" rgba="0.5 1 0.5 1" contype="1" conaffinity="1"/>
            <geom type="box" pos="0.05 -0.04 0" size="0.05 0.005 0.005" rgba=".75 .75 .75 1" contype="1"
                  conaffinity="1"/>
            <geom type="box" pos="0.095 -0.025 0" size="0.005 0.01975 0.005" rgba=".75 .75 .75 1" contype="1"
                  conaffinity="1"/>
            <site name="door_2_handle" pos="0.05 -0.04 0" size="0.01" rgba="1 0 0 1"/>
        </body>

		<light directional="true" ambient="0.2 0.2 0.2" diffuse="0.8 0.8 0.8" specular="0.3 0.3 0.3" castshadow="false" pos="0 0 4" dir="0 0 -1" name="light0"></light>
	</worldbody>
</mujoco>
